<sdf version='1.12'>
  <world name='aic_world'>
    <scene>
      <ambient>0 0 0 1</ambient>
      <grid>false</grid>
      <background>0.150000006 0.150000006 0.150000006 1</background>
      <shadows>true</shadows>
    </scene>
    <gui fullscreen='false'>
      <plugin name='3D View' filename='MinimalScene'>
        <gz-gui>
          <title>3D View</title>
          <property type='bool' key='showTitleBar'>false</property>
          <property type='string' key='state'>docked</property>
        </gz-gui>
        <engine>ogre2</engine>
        <camera_clip>
          <near>0.01</near>
          <far>500</far>
        </camera_clip>
        <camera_pose>0.95 -0.1 1.3 0.0 0.0 3.14</camera_pose>
      </plugin>
      <plugin name='GI' filename='GlobalIlluminationVct'>
        <gz-gui>
          <property type='string' key='state'>docked_collapsed</property>
        </gz-gui>
        <enabled>true</enabled>
        <highQuality>false</highQuality>
        <resolution>256 256 256</resolution>
        <octantCount>1 1 1</octantCount>
        <conserveMemory>true</conserveMemory>
        <thinWallCounter>1.0</thinWallCounter>
        <anisotropic>true</anisotropic>
        <bounceCount>3</bounceCount>
      </plugin>
      <plugin name='Component inspector' filename='ComponentInspector'>
        <gz-gui>
          <property type='string' key='state'>docked_collapsed</property>
        </gz-gui>
      </plugin>
      <plugin name='Entity tree' filename='EntityTree'>
        <gz-gui>
          <property type='string' key='state'>docked_collapsed</property>
        </gz-gui>
      </plugin>
      <plugin name='View angle' filename='ViewAngle'>
        <gz-gui>
          <property type='string' key='state'>docked_collapsed</property>
        </gz-gui>
      </plugin>
      <plugin filename='ApplyForceTorque'>
        <gz-gui>
          <property type='string' key='state'>docked_collapsed</property>
        </gz-gui>
      </plugin>
      <plugin name='Visualize Contacts' filename='VisualizeContacts'>
        <gz-gui>
          <property key='state' type='string'>docked</property>
        </gz-gui>
      </plugin>
    </gui>
    <physics name='2ms' type='bullet-featherstone'>
      <max_step_size>0.002</max_step_size>
      <real_time_factor>1</real_time_factor>
      <real_time_update_rate>1000</real_time_update_rate>
    </physics>
    <plugin name='gz::sim::systems::UserCommands' filename='gz-sim-user-commands-system'/>
    <plugin name='gz::sim::systems::Physics' filename='gz-sim-physics-system'>
      <engine>
        <filename>gz-physics-bullet-featherstone-plugin</filename>
      </engine>
    </plugin>
    <plugin name='gz::sim::systems::Sensors' filename='gz-sim-sensors-system'>
      <render_engine>ogre2</render_engine>
      <global_illumination type='vct'>
        <enabled>true</enabled>
        <resolution>256 256 256</resolution>
        <octant_count>1 1 1</octant_count>
        <bounce_count>3</bounce_count>
        <high_quality>false</high_quality>
        <anisotropic>true</anisotropic>
        <thin_wall_counter>1.0</thin_wall_counter>
        <conserve_memory>true</conserve_memory>
        <debug_vis_mode>none</debug_vis_mode>
      </global_illumination>
    </plugin>
    <plugin name='aic_gazebo::ScoringPlugin' filename='ScoringPlugin'/>
    <plugin name='aic_gazebo::WorldSdfGeneratorPlugin' filename='WorldSdfGeneratorPlugin'>
      <save_world_delay_s>0.1</save_world_delay_s>
      <save_world_path>/tmp/aic.sdf</save_world_path>
      <save_world_delay_s>0.0</save_world_delay_s>
    </plugin>
    <plugin name='gz::sim::systems::Contact' filename='gz-sim-contact-system'/>
    <gravity>0 0 -9.8000000000000007</gravity>
    <magnetic_field>5.5644999999999998e-06 2.2875799999999999e-05 -4.2388400000000002e-05</magnetic_field>
    <atmosphere type='adiabatic'/>
    <model name='enclosure'>
      <link name='enclosure_link'>
        <visual name='enclosure_visual'>
          <geometry>
            <mesh>
              <uri>file:///ws_aic/install/share/aic_assets/models/Enclosure/enclosure_visual.glb</uri>
            </mesh>
          </geometry>
        </visual>
        <visual name='light_visual'>
          <geometry>
            <mesh>
              <uri>file:///ws_aic/install/share/aic_assets/models/Enclosure/light_visual.glb</uri>
            </mesh>
          </geometry>
        </visual>
        <collision name='v1015026001_collider_box'>
          <pose>-0.010998000000000001 0.0092829999999999996 0.56970600000000005 1.5707966535897933 3.4641020661940046e-07 3.1415926535897931</pose>
          <geometry>
            <box>
              <size>1.5 1.138984 1.5</size>
            </box>
          </geometry>
        </collision>
        <collision name='v1015028001_collider_box'>
          <pose>0.71360199999999996 0.73388299999999995 1.3291980000000001 0 0 -3.1415923071795868</pose>
          <geometry>
            <box>
              <size>0.050799999999999998 0.050799999999999998 2.5</size>
            </box>
          </geometry>
        </collision>
        <collision name='v1015013001_collider_box'>
          <pose>-0.010998000000000001 0.0092829999999999996 2.5487989999999998 0 -1.5707959999869179 0</pose>
          <geometry>
            <box>
              <size>0.0608 1.5 1.5</size>
            </box>
          </geometry>
        </collision>
        <collision name='v1015027_collider_box'>
          <pose>-0.73559799999999997 0.73388299999999995 1.3291980000000001 0 0 -3.1415923071795868</pose>
          <geometry>
            <box>
              <size>0.050799999999999998 0.050799999999999998 2.5</size>
            </box>
          </geometry>
        </collision>
        <collision name='v1015029_collider_box'>
          <pose>-0.73559799999999997 -0.71531699999999998 1.3291980000000001 3.1415923071795868 0 -3.1415923071795868</pose>
          <geometry>
            <box>
              <size>0.050799999999999998 0.050799999999999998 2.5</size>
            </box>
          </geometry>
        </collision>
        <collision name='v1015030_collider_box'>
          <pose>0.71360199999999996 -0.71531699999999998 1.3291980000000001 0 0 -3.1415923071795868</pose>
          <geometry>
            <box>
              <size>0.050799999999999998 0.050799999999999998 2.5</size>
            </box>
          </geometry>
        </collision>
        <pose>0 0 0 0 0 0</pose>
        <inertial>
          <pose>0 0 0 0 0 0</pose>
          <mass>1</mass>
          <inertia>
            <ixx>1</ixx>
            <ixy>0</ixy>
            <ixz>0</ixz>
            <iyy>1</iyy>
            <iyz>0</iyz>
            <izz>1</izz>
          </inertia>
        </inertial>
        <enable_wind>false</enable_wind>
      </link>
      <static>true</static>
      <pose>0 0 0 0 0 0</pose>
      <self_collide>false</self_collide>
    </model>
    <model name='enclosure walls'>
      <link name='enclosure_walls_link'>
        <collision name='v1015062006_collider_box'>
          <pose>-0.010998000000000001 0.73428400000000005 1.8287979999999999 1.5707959999999999 0 -1.5707959999999999</pose>
          <geometry>
            <box>
              <size>0.050000999999999997 1.3592 1.3784000000000001</size>
            </box>
          </geometry>
        </collision>
        <collision name='v1015062005_collider_box'>
          <pose>-0.73599800000000004 0.0092829999999999996 1.8287979999999999 1.5707959999999999 0 -1.5707959999999999</pose>
          <geometry>
            <box>
              <size>1.3784000000000001 1.3592 0.050000000000000003</size>
            </box>
          </geometry>
        </collision>
        <collision name='v1015062007_collider_box'>
          <pose>-0.010998000000000001 -0.71571700000000005 1.833799 1.5707959999999999 0 -1.5707959999999999</pose>
          <geometry>
            <box>
              <size>0.050000000000000003 1.3692 1.3784000000000001</size>
            </box>
          </geometry>
        </collision>
        <collision name='v1015062008_collider_box'>
          <pose>0.71400200000000003 0.0092829999999999996 1.833798 1.5707959999999999 0 -1.5707959999999999</pose>
          <geometry>
            <box>
              <size>1.3784000000000001 1.3692 0.050000000000000003</size>
            </box>
          </geometry>
        </collision>
        <pose>0 0 0 0 0 0</pose>
        <inertial>
          <pose>0 0 0 0 0 0</pose>
          <mass>1</mass>
          <inertia>
            <ixx>1</ixx>
            <ixy>0</ixy>
            <ixz>0</ixz>
            <iyy>1</iyy>
            <iyz>0</iyz>
            <izz>1</izz>
          </inertia>
        </inertial>
        <enable_wind>false</enable_wind>
      </link>
      <static>true</static>
      <pose>0 0 0 0 0 0</pose>
      <self_collide>false</self_collide>
    </model>
    <model name='floor'>
      <link name='floor_link'>
        <visual name='floor_visual'>
          <geometry>
            <mesh>
              <uri>file:///ws_aic/install/share/aic_assets/models/Floor/floor_visual.glb</uri>
            </mesh>
          </geometry>
        </visual>
        <visual name='walls_visual'>
          <geometry>
            <mesh>
              <uri>file:///ws_aic/install/share/aic_assets/models/Floor/walls_visual.glb</uri>
            </mesh>
          </geometry>
        </visual>
        <collision name='floor_cylinder'>
          <geometry>
            <plane>
              <size>10 10</size>
              <normal>0 0 1</normal>
            </plane>
          </geometry>
        </collision>
        <pose>0 0 0 0 0 0</pose>
        <inertial>
          <pose>0 0 0 0 0 0</pose>
          <mass>1</mass>
          <inertia>
            <ixx>1</ixx>
            <ixy>0</ixy>
            <ixz>0</ixz>
            <iyy>1</iyy>
            <iyz>0</iyz>
            <izz>1</izz>
          </inertia>
        </inertial>
        <enable_wind>false</enable_wind>
      </link>
      <static>true</static>
      <pose>0 0 0 0 0 0</pose>
      <self_collide>false</self_collide>
    </model>
    <model name='ur5e'>
      <joint name='tabletop_joint' type='fixed'>
        <pose>0 -2.7755575615628914e-17 2.2204460492503131e-16 0 0 0</pose>
        <parent>world</parent>
        <child>tabletop</child>
      </joint>
      <link name='tabletop'>
        <pose>-0.20000000000000001 0.20000000000000001 1.1399999999999999 0 0 -3.141</pose>
        <inertial>
          <pose>0 0 0 0 0 0</pose>
          <mass>4</mass>
          <inertia>
            <ixx>0.0044333315599999999</ixx>
            <ixy>0</ixy>
            <ixz>0</ixz>
            <iyy>0.0044333315599999999</iyy>
            <iyz>0</iyz>
            <izz>0.0071999999999999998</izz>
          </inertia>
        </inertial>
        <collision name='tabletop_fixed_joint_lump__base_link_inertia_collision'>
          <pose>0 0 0 0 0 -2.4492935982947059e-16</pose>
          <geometry>
            <mesh>
              <scale>1 1 1</scale>
              <uri>file:///ws_aic/install/share/ur_description/meshes/ur5e/collision/base.stl</uri>
            </mesh>
          </geometry>
        </collision>
        <visual name='tabletop_fixed_joint_lump__base_link_inertia_visual'>
          <pose>0 0 0 0 0 -2.4492935982947059e-16</pose>
          <geometry>
            <mesh>
              <scale>1 1 1</scale>
              <uri>file:///ws_aic/install/share/ur_description/meshes/ur5e/visual/base.dae</uri>
            </mesh>
          </geometry>
        </visual>
        <enable_wind>false</enable_wind>
      </link>
      <joint name='shoulder_pan_joint' type='revolute'>
        <pose>2.7755575615628914e-17 -2.7755575615628914e-17 0 0 0 0</pose>
        <parent>tabletop</parent>
        <child>shoulder_link</child>
        <axis>
          <xyz>0 0 1</xyz>
          <limit>
            <lower>-6.2831853071795862</lower>
            <upper>6.2831853071795862</upper>
            <effort>150</effort>
            <velocity>3.1415926535897931</velocity>
            <stiffness>100000000</stiffness>
            <dissipation>1</dissipation>
          </limit>
          <dynamics>
            <spring_reference>0</spring_reference>
            <spring_stiffness>0</spring_stiffness>
            <damping>0</damping>
            <friction>0</friction>
          </dynamics>
        </axis>
      </joint>
      <link name='shoulder_link'>
        <pose>-0.19999999941830723 0.1999999979665634 1.3025000551643346 2.339662413181583e-07 -1.3762813322080525e-08 -0.15910278267895583</pose>
        <inertial>
          <pose>0 -0.0019300000000000001 -0.025610000000000001 1.570796326794897 0 0</pose>
          <mass>3.7610000000000001</mass>
          <inertia>
            <ixx>0.0070020999999999998</ixx>
            <ixy>7.3e-07</ixy>
            <ixz>-1.0530000000000001e-05</ixz>
            <iyy>0.0064809100000000003</iyy>
            <iyz>0.00049994000000000004</iyz>
            <izz>0.0065728599999999998</izz>
          </inertia>
        </inertial>
        <collision name='shoulder_link_collision'>
          <pose>0 0 0 0 0 3.1415926535897931</pose>
          <geometry>
            <mesh>
              <scale>1 1 1</scale>
              <uri>file:///ws_aic/install/share/ur_description/meshes/ur5e/collision/shoulder.stl</uri>
            </mesh>
          </geometry>
        </collision>
        <visual name='shoulder_link_visual'>
          <pose>0 0 0 0 0 3.1415926535897931</pose>
          <geometry>
            <mesh>
              <scale>1 1 1</scale>
              <uri>file:///ws_aic/install/share/ur_description/meshes/ur5e/visual/shoulder.dae</uri>
            </mesh>
          </geometry>
        </visual>
        <enable_wind>false</enable_wind>
      </link>
      <joint name='shoulder_lift_joint' type='revolute'>
        <pose>2.7755575615628914e-17 4.4408920985006262e-16 8.3266726846886741e-17 0 0 0</pose>
        <parent>shoulder_link</parent>
        <child>upper_arm_link</child>
        <axis>
          <xyz>0 0 1</xyz>
          <limit>
            <lower>-6.2831853071795862</lower>
            <upper>6.2831853071795862</upper>
            <effort>150</effort>
            <velocity>3.1415926535897931</velocity>
            <stiffness>100000000</stiffness>
            <dissipation>1</dissipation>
          </limit>
          <dynamics>
            <spring_reference>0</spring_reference>
            <spring_stiffness>0</spring_stiffness>
            <damping>0</damping>
            <friction>0</friction>
          </dynamics>
        </axis>
      </joint>
      <link name='upper_arm_link'>
        <pose>-0.20000000511441018 0.1999999406397415 1.302500045264319 1.570795988408654 1.3541832941259826 -0.15910273651666165</pose>
        <inertial>
          <pose>-0.21249999999999999 0 0.11336 0 0 0</pose>
          <mass>8.0579999999999998</mass>
          <inertia>
            <ixx>0.01505885</ixx>
            <ixy>-5.3999999999999998e-05</ixy>
            <ixz>5.6300000000000003e-06</ixz>
            <iyy>0.33388086</iyy>
            <iyz>-1.81e-06</iyz>
            <izz>0.33247207000000001</izz>
          </inertia>
        </inertial>
        <collision name='upper_arm_link_collision'>
          <pose>0 0 0.13800000000000001 1.5707963267948959 5.5511151231257827e-17 -1.5707963267948959</pose>
          <geometry>
            <mesh>
              <scale>1 1 1</scale>
              <uri>file:///ws_aic/install/share/ur_description/meshes/ur5e/collision/upperarm.stl</uri>
            </mesh>
          </geometry>
        </collision>
        <visual name='upper_arm_link_visual'>
          <pose>0 0 0.13800000000000001 1.5707963267948959 5.5511151231257827e-17 -1.5707963267948959</pose>
          <geometry>
            <mesh>
              <scale>1 1 1</scale>
              <uri>file:///ws_aic/install/share/ur_description/meshes/ur5e/visual/upperarm.dae</uri>
            </mesh>
          </geometry>
        </visual>
        <enable_wind>false</enable_wind>
      </link>
      <joint name='elbow_joint' type='revolute'>
        <pose>1.1102230246251565e-16 0 1.1102230246251565e-16 0 0 0</pose>
        <parent>upper_arm_link</parent>
        <child>forearm_link</child>
        <axis>
          <xyz>0 0 1</xyz>
          <limit>
            <lower>-3.1415926535897931</lower>
            <upper>3.1415926535897931</upper>
            <effort>150</effort>
            <velocity>3.1415926535897931</velocity>
            <stiffness>100000000</stiffness>
            <dissipation>1</dissipation>
          </limit>
          <dynamics>
            <spring_reference>0</spring_reference>
            <spring_stiffness>0</spring_stiffness>
            <damping>0</damping>
            <friction>0</friction>
          </dynamics>
        </axis>
      </joint>
      <link name='forearm_link'>
        <pose>-0.29018866213539724 0.21447148515440503 1.717568197302997 -1.5707966818968624 0.12249210195134819 2.9824900711353557</pose>
        <inertial>
          <pose>-0.2422 0 0.026499999999999999 0 0 0</pose>
          <mass>2.8460000000000001</mass>
          <inertia>
            <ixx>0.0039963200000000003</ixx>
            <ixy>-1.365e-05</ixy>
            <ixz>0.00137272</ixz>
            <iyy>0.078792539999999994</iyy>
            <iyz>-6.6000000000000003e-06</iyz>
            <izz>0.078485100000000002</izz>
          </inertia>
        </inertial>
        <collision name='forearm_link_collision'>
          <pose>0 0 0.0070000000000000001 1.5707963267948959 5.5511151231257827e-17 -1.5707963267948959</pose>
          <geometry>
            <mesh>
              <scale>1 1 1</scale>
              <uri>file:///ws_aic/install/share/ur_description/meshes/ur5e/collision/forearm.stl</uri>
            </mesh>
          </geometry>
        </collision>
        <visual name='forearm_link_visual'>
          <pose>0 0 0.0070000000000000001 1.5707963267948959 5.5511151231257827e-17 -1.5707963267948959</pose>
          <geometry>
            <mesh>
              <scale>1 1 1</scale>
              <uri>file:///ws_aic/install/share/ur_description/meshes/ur5e/visual/forearm.dae</uri>
            </mesh>
          </geometry>
        </visual>
        <enable_wind>false</enable_wind>
      </link>
      <joint name='wrist_1_joint' type='revolute'>
        <pose>2.2204460492503131e-16 2.2204460492503131e-16 -1.3877787807814457e-17 0 0 0</pose>
        <parent>forearm_link</parent>
        <child>wrist_1_link</child>
        <axis>
          <xyz>0 0 1</xyz>
          <limit>
            <lower>-6.2831853071795862</lower>
            <upper>6.2831853071795862</upper>
            <effort>28</effort>
            <velocity>3.1415926535897931</velocity>
            <stiffness>100000000</stiffness>
            <dissipation>1</dissipation>
          </limit>
          <dynamics>
            <spring_reference>0</spring_reference>
            <spring_stiffness>0</spring_stiffness>
            <damping>0</damping>
            <friction>0</friction>
          </dynamics>
        </axis>
      </joint>
      <link name='wrist_1_link'>
        <pose>0.073037327329385157 0.021183453197667113 1.7654894913970622 -1.5739297007617368 -1.57070264050909 2.9856236895058226</pose>
        <inertial>
          <pose>0 -0.01634 -0.0018 1.570796326794897 0 0</pose>
          <mass>1.3700000000000001</mass>
          <inertia>
            <ixx>0.0016549100000000001</ixx>
            <ixy>-2.8200000000000001e-06</ixy>
            <ixz>-4.3800000000000004e-06</ixz>
            <iyy>0.00135962</iyy>
            <iyz>0.00010157000000000001</iyz>
            <izz>0.00126279</izz>
          </inertia>
        </inertial>
        <collision name='wrist_1_link_collision'>
          <pose>0 0 -0.127 1.5707963267948959 0 0</pose>
          <geometry>
            <mesh>
              <scale>1 1 1</scale>
              <uri>file:///ws_aic/install/share/ur_description/meshes/ur5e/collision/wrist1.stl</uri>
            </mesh>
          </geometry>
        </collision>
        <visual name='wrist_1_link_visual'>
          <pose>0 0 -0.127 1.5707963267948959 0 0</pose>
          <geometry>
            <mesh>
              <scale>1 1 1</scale>
              <uri>file:///ws_aic/install/share/ur_description/meshes/ur5e/visual/wrist1.dae</uri>
            </mesh>
          </geometry>
        </visual>
        <enable_wind>false</enable_wind>
      </link>
      <joint name='wrist_2_joint' type='revolute'>
        <pose>2.2204460492503131e-16 0 0 3.1467891551475449e-52 -2.5243548967072378e-29 -2.4931432258215426e-23</pose>
        <parent>wrist_1_link</parent>
        <child>wrist_2_link</child>
        <axis>
          <xyz>-2.5243548967072378e-29 3.1467891551475449e-52 1</xyz>
          <limit>
            <lower>-6.2831853071795862</lower>
            <upper>6.2831853071795862</upper>
            <effort>28</effort>
            <velocity>3.1415926535897931</velocity>
            <stiffness>100000000</stiffness>
            <dissipation>1</dissipation>
          </limit>
          <dynamics>
            <spring_reference>0</spring_reference>
            <spring_stiffness>0</spring_stiffness>
            <damping>0</damping>
            <friction>0</friction>
          </dynamics>
        </axis>
      </joint>
      <link name='wrist_2_link'>
        <pose>0.17147807960316555 0.0053878266505477477 1.7654988039317152 -1.5707025671264958 0.00020067040375635042 -1.7298984873724284</pose>
        <inertial>
          <pose>0 0.01634 -0.0018 -1.570796326794897 0 0</pose>
          <mass>1.3</mass>
          <inertia>
            <ixx>0.0013561700000000001</ixx>
            <ixy>-2.74e-06</ixy>
            <ixz>4.4399999999999998e-06</ixz>
            <iyy>0.00127827</iyy>
            <iyz>-5.0479999999999998e-05</iyz>
            <izz>0.00096613999999999999</izz>
          </inertia>
        </inertial>
        <collision name='wrist_2_link_collision'>
          <pose>0 0 -0.099699999999999997 0 0 0</pose>
          <geometry>
            <mesh>
              <scale>1 1 1</scale>
              <uri>file:///ws_aic/install/share/ur_description/meshes/ur5e/collision/wrist2.stl</uri>
            </mesh>
          </geometry>
        </collision>
        <visual name='wrist_2_link_visual'>
          <pose>0 0 -0.099699999999999997 0 0 0</pose>
          <geometry>
            <mesh>
              <scale>1 1 1</scale>
              <uri>file:///ws_aic/install/share/ur_description/meshes/ur5e/visual/wrist2.dae</uri>
            </mesh>
          </geometry>
        </visual>
        <enable_wind>false</enable_wind>
      </link>
      <joint name='wrist_3_joint' type='revolute'>
        <pose>-2.2204460492503131e-16 0 1.6653345369377348e-16 0 -5.4210108624275222e-20 0</pose>
        <parent>wrist_2_link</parent>
        <child>wrist_3_link</child>
        <axis>
          <xyz>-5.4210108624275222e-20 0 1</xyz>
          <limit>
            <lower>-6.2831853071795862</lower>
            <upper>6.2831853071795862</upper>
            <effort>28</effort>
            <velocity>3.1415926535897931</velocity>
            <stiffness>100000000</stiffness>
            <dissipation>1</dissipation>
          </limit>
          <dynamics>
            <spring_reference>0</spring_reference>
            <spring_stiffness>0</spring_stiffness>
            <damping>0</damping>
            <friction>0</friction>
          </dynamics>
        </axis>
      </joint>
      <link name='wrist_3_link'>
        <pose>0.17149060731590871 0.0054060171865834309 1.6658987766862829 3.1414093445815872 0.00012434457711852384 -3.1409040796369112</pose>
        <inertial>
          <pose>1.1467471556274341e-19 -0.00029545404663923193 -0.00075528257887517243 0 0 0</pose>
          <mass>0.72899999999999998</mass>
          <inertia>
            <ixx>0.0020027610676531049</ixx>
            <ixy>6.0000008158546314e-08</ixy>
            <ixz>-1.6999971565549369e-07</ixz>
            <iyy>0.002004962125631113</iyy>
            <iyz>-5.0984543391835843e-06</iyz>
            <izz>0.00060675703240078147</izz>
          </inertia>
        </inertial>
        <collision name='wrist_3_link_collision'>
          <pose>0 0 -0.098900000000000002 1.5707963267948959 0 0</pose>
          <geometry>
            <mesh>
              <scale>1 1 1</scale>
              <uri>file:///ws_aic/install/share/ur_description/meshes/ur5e/collision/wrist3.stl</uri>
            </mesh>
          </geometry>
        </collision>
        <collision name='wrist_3_link_fixed_joint_lump__cam_mount_collider_cylinder_collision_1'>
          <pose>8.6736173798840355e-19 0 -0.005000000000000001 -2.4651903288156619e-32 -2.2204460492503131e-16 2.2204460492503131e-16</pose>
          <geometry>
            <cylinder>
              <length>0.01</length>
              <radius>0.059999999999999998</radius>
            </cylinder>
          </geometry>
        </collision>
        <collision name='wrist_3_link_fixed_joint_lump__cam_mount003_collider_box_collision_2'>
          <pose>0.00025200000000001258 -0.068973999999999994 -0.0071999999999999981 1.570092458683754e-16 -2.5654910149645963e-23 -1.5707959999999999</pose>
          <geometry>
            <box>
              <size>0.055675000000000002 0.036898 0.0044000000000000003</size>
            </box>
          </geometry>
        </collision>
        <collision name='wrist_3_link_fixed_joint_lump__cam_mount003_collider_box.001_collision_3'>
          <pose>0.0001890000000000398 -0.100267 -0.022574 8.5791466926323312e-16 1.3089970000000015 -1.570795999999999</pose>
          <geometry>
            <box>
              <size>0.035256000000000003 0.043249999999999997 0.0085800000000000008</size>
            </box>
          </geometry>
        </collision>
        <collision name='wrist_3_link_fixed_joint_lump__cam_mount003_collider_box.002_collision_4'>
          <pose>0.00025200000000001258 -0.076575000000000004 -0.019057999999999992 1.2516456918772956e-16 0.47996600000000039 -1.5707959999999992</pose>
          <geometry>
            <box>
              <size>0.059567000000000002 0.036898 0.010442</size>
            </box>
          </geometry>
        </collision>
        <collision name='wrist_3_link_fixed_joint_lump__cam_mount003_collider_box.003_collision_5'>
          <pose>0.059859000000000023 -0.034267999999999993 -0.0071999999999999703 5.7469396681546134e-17 -2.1447861203712671e-16 -0.5235989999999997</pose>
          <geometry>
            <box>
              <size>0.055675000000000002 0.036898 0.0044000000000000003</size>
            </box>
          </geometry>
        </collision>
        <collision name='wrist_3_link_fixed_joint_lump__cam_mount003_collider_box.004_collision_6'>
          <pose>0.086928000000000033 -0.049969999999999987 -0.022573999999999979 1.0723933365790339e-16 1.3089969999999995 -0.52359899999999926</pose>
          <geometry>
            <box>
              <size>0.035256000000000003 0.043249999999999997 0.0085800000000000008</size>
            </box>
          </geometry>
        </collision>
        <collision name='wrist_3_link_fixed_joint_lump__cam_mount003_collider_box.005_collision_7'>
          <pose>0.066189999999999999 -0.037923999999999992 -0.01890699999999999 1.8774675604680433e-16 0.47996499999999964 -0.5235989999999997</pose>
          <geometry>
            <box>
              <size>0.060220999999999997 0.036898 0.010442</size>
            </box>
          </geometry>
        </collision>
        <collision name='wrist_3_link_fixed_joint_lump__cam_mount003_collider_box.006_collision_8'>
          <pose>-0.059606999999999993 -0.034705000000000007 -0.007200000000000005 1.398236947969118e-16 3.0735059310348569e-16 -2.6179939999999999</pose>
          <geometry>
            <box>
              <size>0.055675000000000002 0.036898 0.0044000000000000003</size>
            </box>
          </geometry>
        </collision>
        <collision name='wrist_3_link_fixed_joint_lump__cam_mount003_collider_box.007_collision_9'>
          <pose>-0.086739999999999984 -0.050297000000000022 -0.022574000000000011 4.2895733463161824e-16 1.308997000000002 -2.617993999999999</pose>
          <geometry>
            <box>
              <size>0.035256000000000003 0.043249999999999997 0.0085800000000000008</size>
            </box>
          </geometry>
        </collision>
        <collision name='wrist_3_link_fixed_joint_lump__cam_mount003_collider_box.008_collision_10'>
          <pose>-0.066139000000000003 -0.038476000000000017 -0.01902700000000002 3.2855682308190767e-16 0.47996500000000009 -2.617993999999999</pose>
          <geometry>
            <box>
              <size>0.059700000000000003 0.036898 0.010442</size>
            </box>
          </geometry>
        </collision>
        <collision name='wrist_3_link_fixed_joint_lump__body_collider_box_collision_11'>
          <pose>-1.2918180553045391e-09 -0.121045931944188 -0.027474004460981302 -8.5791242802195359e-16 -1.3089963000000004 1.5707962300000011</pose>
          <geometry>
            <box>
              <size>0.048300000000000003 0.029000000000000001 0.029000000000000001</size>
            </box>
          </geometry>
        </collision>
        <collision name='wrist_3_link_fixed_joint_lump__lens_collider_cylinder_collision_12'>
          <pose>-1.4491818856043889e-10 -0.1091971678029513 0.016746072295231371 -2.8734719510251492e-17 0.26180369999999992 1.57079623</pose>
          <geometry>
            <cylinder>
              <length>0.04326</length>
              <radius>0.015630999999999999</radius>
            </cylinder>
          </geometry>
        </collision>
        <collision name='wrist_3_link_fixed_joint_lump__axia80_m20_collider_cylinder_collision_13'>
          <pose>-1.7347234759768071e-18 -4.0000000000013983e-06 0.012699 -3.1415923071795868 -2.220446433842867e-16 2.2204456646576931e-16</pose>
          <geometry>
            <cylinder>
              <length>0.025399000000000001</length>
              <radius>0.041519</radius>
            </cylinder>
          </geometry>
        </collision>
        <collision name='wrist_3_link_fixed_joint_lump__axia80_m20001_collider_cylinder_collision_14'>
          <pose>-1.387778780781446e-17 0.041827999999999997 0.018432 -1.5707959999999999 -1.570092715232855e-16 1.5700922021346527e-16</pose>
          <geometry>
            <cylinder>
              <length>0.016716999999999999</length>
              <radius>0.0060270000000000002</radius>
            </cylinder>
          </geometry>
        </collision>
        <collision name='wrist_3_link_fixed_joint_lump__body_collider_box_collision_15'>
          <pose>-0.1048179144232497 -0.060515968877773621 -0.027472004460981331 -3.2171716050823399e-16 -1.3089963000000009 0.52359902700000038</pose>
          <geometry>
            <box>
              <size>0.048300000000000003 0.029000000000000001 0.029000000000000001</size>
            </box>
          </geometry>
        </collision>
        <collision name='wrist_3_link_fixed_joint_lump__lens_collider_cylinder_collision_16'>
          <pose>-0.094556585162888604 -0.054591584227439392 0.016748072295231349 -3.0171455485764077e-16 0.26180370000000003 0.52359902699999994</pose>
          <geometry>
            <cylinder>
              <length>0.04326</length>
              <radius>0.015630999999999999</radius>
            </cylinder>
          </geometry>
        </collision>
        <collision name='wrist_3_link_fixed_joint_lump__body_collider_box_collision_17'>
          <pose>0.10481791311141191 -0.060515971149941457 -0.027472004460981279 -5.36195267513723e-16 -1.3089963000000009 2.6179934300000012</pose>
          <geometry>
            <box>
              <size>0.048300000000000003 0.029000000000000001 0.029000000000000001</size>
            </box>
          </geometry>
        </collision>
        <collision name='wrist_3_link_fixed_joint_lump__lens_collider_cylinder_collision_18'>
          <pose>0.094556585015724559 -0.054591584482334733 0.016748072295231401 -1.7240831706150901e-16 0.26180370000000042 2.6179934299999998</pose>
          <geometry>
            <cylinder>
              <length>0.04326</length>
              <radius>0.015630999999999999</radius>
            </cylinder>
          </geometry>
        </collision>
        <visual name='wrist_3_link_visual'>
          <pose>0 0 -0.098900000000000002 1.5707963267948959 0 0</pose>
          <geometry>
            <mesh>
              <scale>1 1 1</scale>
              <uri>file:///ws_aic/install/share/ur_description/meshes/ur5e/visual/wrist3.dae</uri>
            </mesh>
          </geometry>
        </visual>
        <visual name='wrist_3_link_fixed_joint_lump__cam_mount_visual_visual_1'>
          <pose>6.9388939039072284e-18 0 -0.026499999999999999 -2.4651903288156619e-32 -2.2204460492503131e-16 2.2204460492503131e-16</pose>
          <geometry>
            <mesh>
              <scale>1 1 1</scale>
              <uri>file:///ws_aic/install/share/aic_assets/models/Camera Mount/cam_mount_visual.glb</uri>
            </mesh>
          </geometry>
        </visual>
        <visual name='wrist_3_link_fixed_joint_lump__basler_cam_visual_visual_2'>
          <pose>4.5102810375396978e-17 -0.1077 -0.033689999999999998 -0.2618037000016864 3.5480430668348004e-06 -1.0474926011160762e-06</pose>
          <geometry>
            <mesh>
              <scale>1 1 1</scale>
              <uri>file:///ws_aic/install/share/aic_assets/models/Basler Camera/basler_cam_visual.glb</uri>
            </mesh>
          </geometry>
        </visual>
        <visual name='wrist_3_link_fixed_joint_lump__axia_ft_sensor_visual_visual_3'>
          <pose>0 0 0 -2.4651903288156619e-32 -2.2204460492503131e-16 2.2204460492503131e-16</pose>
          <geometry>
            <mesh>
              <scale>1 1 1</scale>
              <uri>file:///ws_aic/install/share/aic_assets/models/Axia80 M20/axia_ft_sensor_visual.glb</uri>
            </mesh>
          </geometry>
        </visual>
        <visual name='wrist_3_link_fixed_joint_lump__basler_cam_visual_visual_4'>
          <pose>-0.093259999999999982 -0.053843000000000009 -0.033688000000000017 -0.26180370000168629 3.5480430668413166e-06 -1.047198250492601</pose>
          <geometry>
            <mesh>
              <scale>1 1 1</scale>
              <uri>file:///ws_aic/install/share/aic_assets/models/Basler Camera/basler_cam_visual.glb</uri>
            </mesh>
          </geometry>
        </visual>
        <visual name='wrist_3_link_fixed_joint_lump__basler_cam_visual_visual_5'>
          <pose>0.09326000000000001 -0.053842999999999967 -0.033687999999999982 -0.26180370000168679 3.5480430669800945e-06 1.0471961525073989</pose>
          <geometry>
            <mesh>
              <scale>1 1 1</scale>
              <uri>file:///ws_aic/install/share/aic_assets/models/Basler Camera/basler_cam_visual.glb</uri>
            </mesh>
          </geometry>
        </visual>
        <enable_wind>false</enable_wind>
      </link>
      <joint name='center_camera/attach_sensor_link' type='fixed'>
        <pose>-1.6653345369377348e-16 -2.2204460492503131e-16 4.4408920985006262e-16 -6.7407548053553255e-34 2.7755575615628914e-17 -4.8572257327350599e-17</pose>
        <parent>wrist_3_link</parent>
        <child>center_camera/sensor_link</child>
        <axis>
          <xyz>2.7755575615628914e-17 -6.7407548053553255e-34 1</xyz>
          <limit>
            <lower>-inf</lower>
            <upper>inf</upper>
            <effort>inf</effort>
            <velocity>inf</velocity>
            <stiffness>100000000</stiffness>
            <dissipation>1</dissipation>
          </limit>
          <dynamics>
            <spring_reference>0</spring_reference>
            <spring_stiffness>0</spring_stiffness>
            <damping>0</damping>
            <friction>0</friction>
          </dynamics>
        </axis>
        <physics>
          <ode>
            <limit>
              <cfm>0</cfm>
              <erp>0.20000000000000001</erp>
            </limit>
          </ode>
        </physics>
      </joint>
      <link name='center_camera/sensor_link'>
        <pose>0.1715692758168709 -0.11067478661450833 1.674815549850464 3.1411115542121992 1.3088136979059968 1.571020268112679</pose>
        <inertial>
          <pose>0 0 0 0 0 0</pose>
          <mass>0.001</mass>
          <inertia>
            <ixx>9.9999999999999995e-07</ixx>
            <ixy>0</ixy>
            <ixz>0</ixz>
            <iyy>9.9999999999999995e-07</iyy>
            <iyz>0</iyz>
            <izz>9.9999999999999995e-07</izz>
          </inertia>
        </inertial>
        <sensor name='center_camera' type='camera'>
          <pose>-1.6653345369377348e-16 -2.2204460492503131e-16 4.4408920985006262e-16 -6.7407548053553255e-34 2.7755575615628914e-17 -4.8572257327350599e-17</pose>
          <frame_id>center_camera/sensor_link</frame_id>
          <topic>/center_camera/image</topic>
          <update_rate>20</update_rate>
          <enable_metrics>false</enable_metrics>
          <camera name='center_camera'>
            <pose>0 0 0 0 0 0</pose>
            <horizontal_fov>0.87180000000000002</horizontal_fov>
            <image>
              <width>1152</width>
              <height>1024</height>
              <format>RGB_INT8</format>
              <anti_aliasing>4</anti_aliasing>
            </image>
            <camera_info_topic>/center_camera/camera_info</camera_info_topic>
            <trigger_topic></trigger_topic>
            <triggered>false</triggered>
            <clip>
              <near>0.070000000000000007</near>
              <far>20</far>
            </clip>
            <save enabled='false'>
              <path>__default__</path>
            </save>
            <visibility_mask>4294967295</visibility_mask>
            <noise>
              <type>none</type>
              <mean>0</mean>
              <stddev>0</stddev>
            </noise>
            <distortion>
              <k1>0</k1>
              <k2>0</k2>
              <k3>0</k3>
              <p1>0</p1>
              <p2>0</p2>
              <center>0.5 0.5</center>
            </distortion>
            <lens>
              <type>stereographic</type>
              <scale_to_hfov>true</scale_to_hfov>
              <cutoff_angle>1.5707963267948966</cutoff_angle>
              <env_texture_size>256</env_texture_size>
            </lens>
            <optical_frame_id>center_camera/optical</optical_frame_id>
          </camera>
        </sensor>
        <enable_wind>false</enable_wind>
      </link>
      <joint name='center_camera/attach_optical' type='fixed'>
        <pose>2.2204460492503131e-16 4.4408920985006262e-16 0 0 5.4210108624275222e-20 0</pose>
        <parent>center_camera/sensor_link</parent>
        <child>center_camera/optical</child>
        <axis>
          <xyz>5.4210108624275222e-20 0 1</xyz>
          <limit>
            <lower>-inf</lower>
            <upper>inf</upper>
            <effort>inf</effort>
            <velocity>inf</velocity>
            <stiffness>100000000</stiffness>
            <dissipation>1</dissipation>
          </limit>
          <dynamics>
            <spring_reference>0</spring_reference>
            <spring_stiffness>0</spring_stiffness>
            <damping>0</damping>
            <friction>0</friction>
          </dynamics>
        </axis>
        <physics>
          <ode>
            <limit>
              <cfm>0</cfm>
              <erp>0.20000000000000001</erp>
            </limit>
          </ode>
        </physics>
      </joint>
      <link name='center_camera/optical'>
        <pose>0.1715692758168709 -0.11067478661450833 1.674815549850464 2.8796059121499131 0.0001209955944448018 -3.1409026715124702</pose>
        <inertial>
          <pose>0 0 0 0 0 0</pose>
          <mass>0.001</mass>
          <inertia>
            <ixx>9.9999999999999995e-07</ixx>
            <ixy>0</ixy>
            <ixz>0</ixz>
            <iyy>9.9999999999999995e-07</iyy>
            <iyz>0</iyz>
            <izz>9.9999999999999995e-07</izz>
          </inertia>
        </inertial>
        <enable_wind>false</enable_wind>
      </link>
      <joint name='ati/attach_joint' type='fixed'>
        <pose>-2.2204460492503131e-16 2.2204460492503131e-16 2.2204460492503131e-16 0 -5.4210108624275222e-20 0</pose>
        <parent>wrist_3_link</parent>
        <child>ati/tool_link</child>
        <axis>
          <xyz>-5.4210108624275222e-20 0 1</xyz>
          <limit>
            <lower>-inf</lower>
            <upper>inf</upper>
            <effort>inf</effort>
            <velocity>inf</velocity>
            <stiffness>100000000</stiffness>
            <dissipation>1</dissipation>
          </limit>
          <dynamics>
            <spring_reference>0</spring_reference>
            <spring_stiffness>0</spring_stiffness>
            <damping>0</damping>
            <friction>0</friction>
          </dynamics>
        </axis>
        <physics>
          <ode>
            <limit>
              <cfm>0</cfm>
              <erp>0.20000000000000001</erp>
            </limit>
          </ode>
        </physics>
        <sensor name='AtiForceTorqueSensor' type='force_torque'>
          <pose>-2.2204460492503131e-16 2.2204460492503131e-16 2.2204460492503131e-16 0 -5.4210108624275222e-20 0</pose>
          <frame_id></frame_id>
          <topic>/axia80_m20/wrench</topic>
          <update_rate>100</update_rate>
          <enable_metrics>false</enable_metrics>
          <force_torque>
            <frame>sensor</frame>
            <measure_direction>child_to_parent</measure_direction>
            <force>
              <x>
                <noise type='gaussian'>
                  <mean>0</mean>
                  <stddev>0.20000000000000001</stddev>
                  <bias_mean>0</bias_mean>
                  <bias_stddev>0</bias_stddev>
                  <dynamic_bias_stddev>0</dynamic_bias_stddev>
                  <dynamic_bias_correlation_time>0</dynamic_bias_correlation_time>
                  <precision>0</precision>
                </noise>
              </x>
              <y>
                <noise type='gaussian'>
                  <mean>0</mean>
                  <stddev>0.20000000000000001</stddev>
                  <bias_mean>0</bias_mean>
                  <bias_stddev>0</bias_stddev>
                  <dynamic_bias_stddev>0</dynamic_bias_stddev>
                  <dynamic_bias_correlation_time>0</dynamic_bias_correlation_time>
                  <precision>0</precision>
                </noise>
              </y>
              <z>
                <noise type='gaussian'>
                  <mean>0</mean>
                  <stddev>0.20000000000000001</stddev>
                  <bias_mean>0</bias_mean>
                  <bias_stddev>0</bias_stddev>
                  <dynamic_bias_stddev>0</dynamic_bias_stddev>
                  <dynamic_bias_correlation_time>0</dynamic_bias_correlation_time>
                  <precision>0</precision>
                </noise>
              </z>
            </force>
            <torque>
              <x>
                <noise type='gaussian'>
                  <mean>0</mean>
                  <stddev>0.050000000000000003</stddev>
                  <bias_mean>0</bias_mean>
                  <bias_stddev>0</bias_stddev>
                  <dynamic_bias_stddev>0</dynamic_bias_stddev>
                  <dynamic_bias_correlation_time>0</dynamic_bias_correlation_time>
                  <precision>0</precision>
                </noise>
              </x>
              <y>
                <noise type='gaussian'>
                  <mean>0</mean>
                  <stddev>0.050000000000000003</stddev>
                  <bias_mean>0</bias_mean>
                  <bias_stddev>0</bias_stddev>
                  <dynamic_bias_stddev>0</dynamic_bias_stddev>
                  <dynamic_bias_correlation_time>0</dynamic_bias_correlation_time>
                  <precision>0</precision>
                </noise>
              </y>
              <z>
                <noise type='gaussian'>
                  <mean>0</mean>
                  <stddev>0.050000000000000003</stddev>
                  <bias_mean>0</bias_mean>
                  <bias_stddev>0</bias_stddev>
                  <dynamic_bias_stddev>0</dynamic_bias_stddev>
                  <dynamic_bias_correlation_time>0</dynamic_bias_correlation_time>
                  <precision>0</precision>
                </noise>
              </z>
            </torque>
          </force_torque>
        </sensor>
      </joint>
      <link name='ati/tool_link'>
        <pose>0.17149351832798895 0.0054105788001206547 1.641398801803589 3.1414095355327003 0.00012458997570453253 -3.1409036828721071</pose>
        <inertial>
          <pose>0 0 0 0 0 0</pose>
          <mass>1.0009999999999999</mass>
          <inertia>
            <ixx>0.10000100000000001</ixx>
            <ixy>0</ixy>
            <ixz>0</ixz>
            <iyy>0.10000100000000001</iyy>
            <iyz>0</iyz>
            <izz>0.10000100000000001</izz>
          </inertia>
        </inertial>
        <collision name='ati/tool_link_fixed_joint_lump__body_collider_cylinder_collision'>
          <pose>0 0 0.06855 -3.1415923071795868 0 1.5707960000000001</pose>
          <geometry>
            <cylinder>
              <length>0.11310000000000001</length>
              <radius>0.037999999999999999</radius>
            </cylinder>
          </geometry>
        </collision>
        <collision name='ati/tool_link_fixed_joint_lump__cylinder003_collider_cylinder_collision_1'>
          <pose>0 0 0.0060000000000000001 0 0 0</pose>
          <geometry>
            <cylinder>
              <length>0.012</length>
              <radius>0.042999999999999997</radius>
            </cylinder>
          </geometry>
        </collision>
        <visual name='ati/tool_link_fixed_joint_lump__hande_base_visual_visual'>
          <pose>0 0 0 0 0 0</pose>
          <geometry>
            <mesh>
              <scale>1 1 1</scale>
              <uri>file:///ws_aic/install/share/aic_assets/models/Robotiq Hand-E/hande_base_visual.glb</uri>
            </mesh>
          </geometry>
        </visual>
        <enable_wind>false</enable_wind>
      </link>
      <joint name='gripper/left_finger_joint' type='prismatic'>
        <pose>-2.2204460492503131e-16 2.2204460492503131e-16 2.2204460492503131e-16 0 -5.4210108624275222e-20 0</pose>
        <parent>ati/tool_link</parent>
        <child>gripper/hande_finger_link_l</child>
        <axis>
          <xyz>1 0 5.4210108624275222e-20</xyz>
          <limit>
            <lower>0</lower>
            <upper>0.025000000000000001</upper>
            <effort>130</effort>
            <velocity>0.050000000000000003</velocity>
            <stiffness>100000000</stiffness>
            <dissipation>1</dissipation>
          </limit>
          <dynamics>
            <spring_reference>0</spring_reference>
            <spring_stiffness>0</spring_stiffness>
            <damping>0</damping>
            <friction>0</friction>
          </dynamics>
        </axis>
      </joint>
      <link name='gripper/hande_finger_link_l'>
        <pose>0.16441257593563904 0.0054056316154965454 1.6413979673385621 3.1414095355327003 0.00012458997570453253 -3.1409036828721071</pose>
        <inertial>
          <pose>0 0 0 0 0 0</pose>
          <mass>0.001</mass>
          <inertia>
            <ixx>0.0001</ixx>
            <ixy>0</ixy>
            <ixz>0</ixz>
            <iyy>9.0000000000000006e-05</iyy>
            <iyz>0</iyz>
            <izz>3.0000000000000001e-05</izz>
          </inertia>
        </inertial>
        <collision name='gripper/hande_finger_link_l_fixed_joint_lump__finger_collider_box_collision'>
          <pose>0.0075949999999999976 -1.0000000000000001e-05 0.13813800000000001 0 0 0</pose>
          <geometry>
            <box>
              <size>0.0078390000000000005 0.021000000000000001 0.028622000000000002</size>
            </box>
          </geometry>
        </collision>
        <collision name='gripper/hande_finger_link_l_fixed_joint_lump__finger_collider_box001_collision_1'>
          <pose>0.0029999999999999992 -1.0000000000000001e-05 0.16145000000000001 0 0 0</pose>
          <geometry>
            <box>
              <size>0.0060000000000000001 0.021000000000000001 0.021498</size>
            </box>
          </geometry>
        </collision>
        <collision name='gripper/hande_finger_link_l_fixed_joint_lump__finger_collider_box002_collision_2'>
          <pose>-0.010645999999999999 -0.014999999999999999 0.124725 0 0 0</pose>
          <geometry>
            <box>
              <size>0.044318999999999997 0.0074999999999999997 0.0039490000000000003</size>
            </box>
          </geometry>
        </collision>
        <collision name='gripper/hande_finger_link_l_fixed_joint_lump__finger_collider_box003_collision_3'>
          <pose>0.0020459999999999992 -0.0095399999999999999 0.12906400000000001 0 0 0</pose>
          <geometry>
            <box>
              <size>0.017387 0.018419000000000001 0.0092709999999999997</size>
            </box>
          </geometry>
        </collision>
        <visual name='gripper/hande_finger_link_l_fixed_joint_lump__hande_finger_visual_visual'>
          <pose>-0.025000000000000001 0 0 0 0 0</pose>
          <geometry>
            <mesh>
              <scale>1 1 1</scale>
              <uri>file:///ws_aic/install/share/aic_assets/models/Robotiq Hand-E/hande_finger_visual.glb</uri>
            </mesh>
          </geometry>
        </visual>
        <enable_wind>false</enable_wind>
      </link>
      <joint name='gripper/right_finger_joint' type='prismatic'>
        <pose>-2.2204460492503131e-16 2.2204460492503131e-16 2.2204460492503131e-16 0 -5.4210108624275222e-20 0</pose>
        <parent>ati/tool_link</parent>
        <child>gripper/hande_finger_link_r</child>
        <axis>
          <xyz>-1 0 -5.4210108624275222e-20</xyz>
          <limit>
            <lower>0</lower>
            <upper>0.025000000000000001</upper>
            <effort>130</effort>
            <velocity>0.050000000000000003</velocity>
            <stiffness>100000000</stiffness>
            <dissipation>1</dissipation>
          </limit>
          <dynamics>
            <spring_reference>0</spring_reference>
            <spring_stiffness>0</spring_stiffness>
            <damping>0</damping>
            <friction>0</friction>
          </dynamics>
          <mimic joint='gripper/left_finger_joint' axis='axis'>
            <multiplier>1</multiplier>
            <offset>0</offset>
            <reference>0</reference>
          </mimic>
        </axis>
      </joint>
      <link name='gripper/hande_finger_link_r'>
        <pose>0.17824368474415775 0.0054152130604013726 1.6413996362686158 3.1414095355327003 0.00012458997570453253 -3.1409036828721071</pose>
        <inertial>
          <pose>0 0 0 0 0 0</pose>
          <mass>0.001</mass>
          <inertia>
            <ixx>0.0001</ixx>
            <ixy>0</ixy>
            <ixz>0</ixz>
            <iyy>9.0000000000000006e-05</iyy>
            <iyz>0</iyz>
            <izz>3.0000000000000001e-05</izz>
          </inertia>
        </inertial>
        <collision name='gripper/hande_finger_link_r_fixed_joint_lump__finger_collider_box_collision'>
          <pose>-0.0075949999999999976 -1.0000000000000001e-05 0.13813800000000001 0 0 0</pose>
          <geometry>
            <box>
              <size>0.0078390000000000005 0.021000000000000001 0.028622000000000002</size>
            </box>
          </geometry>
        </collision>
        <collision name='gripper/hande_finger_link_r_fixed_joint_lump__finger_collider_box001_collision_1'>
          <pose>-0.0029999999999999992 -1.0000000000000001e-05 0.16145000000000001 0 0 0</pose>
          <geometry>
            <box>
              <size>0.0060000000000000001 0.021000000000000001 0.021498</size>
            </box>
          </geometry>
        </collision>
        <collision name='gripper/hande_finger_link_r_fixed_joint_lump__finger_collider_box002_collision_2'>
          <pose>0.010645999999999999 -0.014999999999999999 0.124725 0 0 0</pose>
          <geometry>
            <box>
              <size>0.044318999999999997 0.0074999999999999997 0.0039490000000000003</size>
            </box>
          </geometry>
        </collision>
        <collision name='gripper/hande_finger_link_r_fixed_joint_lump__finger_collider_box003_collision_3'>
          <pose>-0.0020459999999999992 -0.0095399999999999999 0.12906400000000001 0 0 0</pose>
          <geometry>
            <box>
              <size>0.017387 0.018419000000000001 0.0092709999999999997</size>
            </box>
          </geometry>
        </collision>
        <visual name='gripper/hande_finger_link_r_fixed_joint_lump__hande_finger_visual_visual'>
          <pose>0.025000000000000001 0 0 0 0 3.1415700000000002</pose>
          <geometry>
            <mesh>
              <scale>1 1 1</scale>
              <uri>file:///ws_aic/install/share/aic_assets/models/Robotiq Hand-E/hande_finger_visual.glb</uri>
            </mesh>
          </geometry>
        </visual>
        <enable_wind>false</enable_wind>
      </link>
      <joint name='left_camera/attach_sensor_link' type='fixed'>
        <pose>-9.7144514654701197e-17 -2.2204460492503131e-16 4.4408920985006262e-16 -1.1102230246251565e-16 -1.5407439555097887e-33 -2.7755575615628914e-17</pose>
        <parent>wrist_3_link</parent>
        <child>left_camera/sensor_link</child>
        <axis>
          <xyz>1.5407439555097887e-33 1.1102230246251565e-16 1</xyz>
          <limit>
            <lower>-inf</lower>
            <upper>inf</upper>
            <effort>inf</effort>
            <velocity>inf</velocity>
            <stiffness>100000000</stiffness>
            <dissipation>1</dissipation>
          </limit>
          <dynamics>
            <spring_reference>0</spring_reference>
            <spring_stiffness>0</spring_stiffness>
            <damping>0</damping>
            <friction>0</friction>
          </dynamics>
        </axis>
        <physics>
          <ode>
            <limit>
              <cfm>0</cfm>
              <erp>0.20000000000000001</erp>
            </limit>
          </ode>
        </physics>
      </joint>
      <link name='left_camera/sensor_link'>
        <pose>0.27204597291148175 -0.052558976471300575 1.6748366498947145 3.1407394977969356 1.3090121997652377 2.6178582473372294</pose>
        <inertial>
          <pose>0 0 0 0 0 0</pose>
          <mass>0.001</mass>
          <inertia>
            <ixx>9.9999999999999995e-07</ixx>
            <ixy>0</ixy>
            <ixz>0</ixz>
            <iyy>9.9999999999999995e-07</iyy>
            <iyz>0</iyz>
            <izz>9.9999999999999995e-07</izz>
          </inertia>
        </inertial>
        <sensor name='left_camera' type='camera'>
          <pose>-9.7144514654701197e-17 -2.2204460492503131e-16 4.4408920985006262e-16 -1.1102230246251565e-16 -1.5407439555097887e-33 -2.7755575615628914e-17</pose>
          <frame_id>left_camera/sensor_link</frame_id>
          <topic>/left_camera/image</topic>
          <update_rate>20</update_rate>
          <enable_metrics>false</enable_metrics>
          <camera name='left_camera'>
            <pose>0 0 0 0 0 0</pose>
            <horizontal_fov>0.87180000000000002</horizontal_fov>
            <image>
              <width>1152</width>
              <height>1024</height>
              <format>RGB_INT8</format>
              <anti_aliasing>4</anti_aliasing>
            </image>
            <camera_info_topic>/left_camera/camera_info</camera_info_topic>
            <trigger_topic></trigger_topic>
            <triggered>false</triggered>
            <clip>
              <near>0.070000000000000007</near>
              <far>20</far>
            </clip>
            <save enabled='false'>
              <path>__default__</path>
            </save>
            <visibility_mask>4294967295</visibility_mask>
            <noise>
              <type>none</type>
              <mean>0</mean>
              <stddev>0</stddev>
            </noise>
            <distortion>
              <k1>0</k1>
              <k2>0</k2>
              <k3>0</k3>
              <p1>0</p1>
              <p2>0</p2>
              <center>0.5 0.5</center>
            </distortion>
            <lens>
              <type>stereographic</type>
              <scale_to_hfov>true</scale_to_hfov>
              <cutoff_angle>1.5707963267948966</cutoff_angle>
              <env_texture_size>256</env_texture_size>
            </lens>
            <optical_frame_id>left_camera/optical</optical_frame_id>
          </camera>
        </sensor>
        <enable_wind>false</enable_wind>
      </link>
      <joint name='left_camera/attach_optical' type='fixed'>
        <pose>0 5.5511151231257827e-17 2.7755575615628914e-16 -4.622231866529366e-33 -5.5511151231257827e-17 1.6653345369377348e-16</pose>
        <parent>left_camera/sensor_link</parent>
        <child>left_camera/optical</child>
        <axis>
          <xyz>-5.5511151231257827e-17 -4.622231866529366e-33 1</xyz>
          <limit>
            <lower>-inf</lower>
            <upper>inf</upper>
            <effort>inf</effort>
            <velocity>inf</velocity>
            <stiffness>100000000</stiffness>
            <dissipation>1</dissipation>
          </limit>
          <dynamics>
            <spring_reference>0</spring_reference>
            <spring_stiffness>0</spring_stiffness>
            <damping>0</damping>
            <friction>0</friction>
          </dynamics>
        </axis>
        <physics>
          <ode>
            <limit>
              <cfm>0</cfm>
              <erp>0.20000000000000001</erp>
            </limit>
          </ode>
        </physics>
      </joint>
      <link name='left_camera/optical'>
        <pose>0.27204597291148175 -0.052558976471300575 1.6748366498947145 2.8798053465114215 0.00021723997543098594 -2.0937054783071183</pose>
        <inertial>
          <pose>0 0 0 0 0 0</pose>
          <mass>0.001</mass>
          <inertia>
            <ixx>9.9999999999999995e-07</ixx>
            <ixy>0</ixy>
            <ixz>0</ixz>
            <iyy>9.9999999999999995e-07</iyy>
            <iyz>0</iyz>
            <izz>9.9999999999999995e-07</izz>
          </inertia>
        </inertial>
        <enable_wind>false</enable_wind>
      </link>
      <joint name='right_camera/attach_sensor_link' type='fixed'>
        <pose>1.1102230246251565e-16 0 0 1.1102230246251565e-16 1.1102230246251565e-16 6.1629758220391547e-33</pose>
        <parent>wrist_3_link</parent>
        <child>right_camera/sensor_link</child>
        <axis>
          <xyz>1.1102230246251565e-16 -1.1102230246251565e-16 1</xyz>
          <limit>
            <lower>-inf</lower>
            <upper>inf</upper>
            <effort>inf</effort>
            <velocity>inf</velocity>
            <stiffness>100000000</stiffness>
            <dissipation>1</dissipation>
          </limit>
          <dynamics>
            <spring_reference>0</spring_reference>
            <spring_stiffness>0</spring_stiffness>
            <damping>0</damping>
            <friction>0</friction>
          </dynamics>
        </axis>
        <physics>
          <ode>
            <limit>
              <cfm>0</cfm>
              <erp>0.20000000000000001</erp>
            </limit>
          </ode>
        </physics>
      </joint>
      <link name='right_camera/sensor_link'>
        <pose>0.071012753216373098 -0.05269743803578221 1.6748116159439088 -3.1412209776191289 1.3087971423368501 0.52464684946749252</pose>
        <inertial>
          <pose>0 0 0 0 0 0</pose>
          <mass>0.001</mass>
          <inertia>
            <ixx>9.9999999999999995e-07</ixx>
            <ixy>0</ixy>
            <ixz>0</ixz>
            <iyy>9.9999999999999995e-07</iyy>
            <iyz>0</iyz>
            <izz>9.9999999999999995e-07</izz>
          </inertia>
        </inertial>
        <sensor name='right_camera' type='camera'>
          <pose>1.1102230246251565e-16 0 0 1.1102230246251565e-16 1.1102230246251565e-16 6.1629758220391547e-33</pose>
          <frame_id>right_camera/sensor_link</frame_id>
          <topic>/right_camera/image</topic>
          <update_rate>20</update_rate>
          <enable_metrics>false</enable_metrics>
          <camera name='right_camera'>
            <pose>0 0 0 0 0 0</pose>
            <horizontal_fov>0.87180000000000002</horizontal_fov>
            <image>
              <width>1152</width>
              <height>1024</height>
              <format>RGB_INT8</format>
              <anti_aliasing>4</anti_aliasing>
            </image>
            <camera_info_topic>/right_camera/camera_info</camera_info_topic>
            <trigger_topic></trigger_topic>
            <triggered>false</triggered>
            <clip>
              <near>0.070000000000000007</near>
              <far>20</far>
            </clip>
            <save enabled='false'>
              <path>__default__</path>
            </save>
            <visibility_mask>4294967295</visibility_mask>
            <noise>
              <type>none</type>
              <mean>0</mean>
              <stddev>0</stddev>
            </noise>
            <distortion>
              <k1>0</k1>
              <k2>0</k2>
              <k3>0</k3>
              <p1>0</p1>
              <p2>0</p2>
              <center>0.5 0.5</center>
            </distortion>
            <lens>
              <type>stereographic</type>
              <scale_to_hfov>true</scale_to_hfov>
              <cutoff_angle>1.5707963267948966</cutoff_angle>
              <env_texture_size>256</env_texture_size>
            </lens>
            <optical_frame_id>right_camera/optical</optical_frame_id>
          </camera>
        </sensor>
        <enable_wind>false</enable_wind>
      </link>
      <joint name='right_camera/attach_optical' type='fixed'>
        <pose>0 0 -1.1102230246251565e-16 0 0 0</pose>
        <parent>right_camera/sensor_link</parent>
        <child>right_camera/optical</child>
        <axis>
          <xyz>0 0 1</xyz>
          <limit>
            <lower>-inf</lower>
            <upper>inf</upper>
            <effort>inf</effort>
            <velocity>inf</velocity>
            <stiffness>100000000</stiffness>
            <dissipation>1</dissipation>
          </limit>
          <dynamics>
            <spring_reference>0</spring_reference>
            <spring_stiffness>0</spring_stiffness>
            <damping>0</damping>
            <friction>0</friction>
          </dynamics>
        </axis>
        <physics>
          <ode>
            <limit>
              <cfm>0</cfm>
              <erp>0.20000000000000001</erp>
            </limit>
          </ode>
        </physics>
      </joint>
      <link name='right_camera/optical'>
        <pose>0.071012753216373098 -0.05269743803578221 1.6748116159439088 2.879589559950654 -9.9907548322984989e-05 2.0950850707610211</pose>
        <inertial>
          <pose>0 0 0 0 0 0</pose>
          <mass>0.001</mass>
          <inertia>
            <ixx>9.9999999999999995e-07</ixx>
            <ixy>0</ixy>
            <ixz>0</ixz>
            <iyy>9.9999999999999995e-07</iyy>
            <iyz>0</iyz>
            <izz>9.9999999999999995e-07</izz>
          </inertia>
        </inertial>
        <enable_wind>false</enable_wind>
      </link>
      <plugin name='gz_ros2_control::GazeboSimROS2ControlPlugin' filename='gz_ros2_control-system'>
        <parameters>/ws_aic/install/share/aic_bringup/config/aic_ros2_controllers.yaml</parameters>
        <ros>
          <namespace/>
        </ros>
      </plugin>
      <plugin name='gz::sim::systems::ForceTorque' filename='gz-sim-forcetorque-system'/>
      <plugin name='aic_gazebo::OffLimitContactsPlugin' filename='OffLimitContactsPlugin'>
        <update_rate>5</update_rate>
        <topic>/aic/gazebo/contacts/off_limit</topic>
        <off_limit_models>
          <model>enclosure</model>
          <model>enclosure walls</model>
          <model>task_board</model>
        </off_limit_models>
      </plugin>
      <plugin name='aic_gazebo::ResetJointsPlugin' filename='ResetJointsPlugin'/>
      <frame name='base_link-base_fixed_joint' attached_to='base_link'>
        <pose>0 0 0 0 0 3.1415926535897931</pose>
      </frame>
      <frame name='base' attached_to='base_link-base_fixed_joint'>
        <pose>0 0 0 0 0 0</pose>
      </frame>
      <frame name='base_link-base_link_inertia' attached_to='base_link'>
        <pose>0 0 0 0 0 3.1415926535897931</pose>
      </frame>
      <frame name='base_link_inertia' attached_to='base_link-base_link_inertia'>
        <pose>0 0 0 0 0 0</pose>
      </frame>
      <frame name='attach_center_camera' attached_to='cam_mount/cam_mount_link'>
        <pose>0 -0.1077 -0.0071900000000000002 8.5791242802195418e-16 -1.3089963 1.5707962299999996</pose>
      </frame>
      <frame name='center_camera/camera_link' attached_to='attach_center_camera'>
        <pose>0 0 0 0 0 0</pose>
      </frame>
      <frame name='attach_ft_sensor_joint' attached_to='cam_mount/cam_mount_link'>
        <pose>0 0 0.026499999999999999 0 0 0</pose>
      </frame>
      <frame name='ati/base_link' attached_to='attach_ft_sensor_joint'>
        <pose>0 0 0 0 0 0</pose>
      </frame>
      <frame name='gripper/attach_tool_frame' attached_to='gripper/hande_base_link'>
        <pose>0 0 0.17199999999999999 0 0 0</pose>
      </frame>
      <frame name='gripper/tcp' attached_to='gripper/attach_tool_frame'>
        <pose>0 0 0 0 0 0</pose>
      </frame>
      <frame name='attach_gripper' attached_to='ati/tool_link'>
        <pose>0 0 0 0 0 0</pose>
      </frame>
      <frame name='gripper/hande_base_link' attached_to='attach_gripper'>
        <pose>0 0 0 0 0 0</pose>
      </frame>
      <frame name='attach_left_camera' attached_to='cam_mount/cam_mount_link'>
        <pose>-0.093259999999999996 -0.053843000000000002 -0.0071879999999999999 -1.0723905350274467e-16 -1.3089963000000009 0.52359902700000027</pose>
      </frame>
      <frame name='left_camera/camera_link' attached_to='attach_left_camera'>
        <pose>0 0 0 0 0 0</pose>
      </frame>
      <frame name='attach_right_camera' attached_to='cam_mount/cam_mount_link'>
        <pose>0.093259999999999996 -0.053843000000000002 -0.0071879999999999999 1.0723905350274467e-16 -1.3089963000000009 2.6179934299999994</pose>
      </frame>
      <frame name='right_camera/camera_link' attached_to='attach_right_camera'>
        <pose>0 0 0 0 0 0</pose>
      </frame>
      <frame name='attach_cam_mount' attached_to='tool0'>
        <pose>0 0 -0.026499999999999999 0 0 0</pose>
      </frame>
      <frame name='cam_mount/cam_mount_link' attached_to='attach_cam_mount'>
        <pose>0 0 0 0 0 0</pose>
      </frame>
      <frame name='flange-tool0' attached_to='flange'>
        <pose>0 0 0 1.5707963267948959 -5.5511151231257827e-17 1.5707963267948959</pose>
      </frame>
      <frame name='tool0' attached_to='flange-tool0'>
        <pose>0 0 0 0 0 0</pose>
      </frame>
      <frame name='wrist_3-flange' attached_to='wrist_3_link'>
        <pose>0 0 0 -1.5707963267948957 -1.5707963267948966 0</pose>
      </frame>
      <frame name='flange' attached_to='wrist_3-flange'>
        <pose>0 0 0 0 0 0</pose>
      </frame>
      <frame name='wrist_3_link-ft_frame' attached_to='wrist_3_link'>
        <pose>0 0 0 3.1415926535897931 0 0</pose>
      </frame>
      <frame name='ft_frame' attached_to='wrist_3_link-ft_frame'>
        <pose>0 0 0 0 0 0</pose>
      </frame>
      <frame name='base_joint' attached_to='tabletop'>
        <pose>0 0 0 0 0 0</pose>
      </frame>
      <frame name='base_link' attached_to='base_joint'>
        <pose>0 0 0 0 0 0</pose>
      </frame>
      <pose>-2.9550308588977003e-09 3.0054336519480529e-09 -1.4305114870438729e-08 0 0 1.2600703668528146e-10</pose>
      <static>false</static>
      <self_collide>false</self_collide>
    </model>
    <light name='enclosure_light' type='spot'>
      <pose>0 0 2.5 0 0 0</pose>
      <cast_shadows>true</cast_shadows>
      <intensity>0.40000000000000002</intensity>
      <direction>0 0 -1</direction>
      <diffuse>1 1 1 1</diffuse>
      <specular>0.100000001 0.100000001 0.100000001 1</specular>
      <attenuation>
        <range>2</range>
        <linear>0.01</linear>
        <constant>1</constant>
        <quadratic>0.001</quadratic>
      </attenuation>
      <spot>
        <inner_angle>0.10000000000000001</inner_angle>
        <outer_angle>2</outer_angle>
        <falloff>1</falloff>
      </spot>
    </light>
    <light name='ceiling_01' type='point'>
      <pose>2 2 6 0 0 0</pose>
      <cast_shadows>false</cast_shadows>
      <intensity>2</intensity>
      <direction>0 0 -1</direction>
      <diffuse>1 1 1 1</diffuse>
      <specular>0.100000001 0.100000001 0.100000001 1</specular>
      <attenuation>
        <range>9</range>
        <linear>0.01</linear>
        <constant>1</constant>
        <quadratic>0.001</quadratic>
      </attenuation>
      <spot>
        <inner_angle>0</inner_angle>
        <outer_angle>0</outer_angle>
        <falloff>0</falloff>
      </spot>
    </light>
    <light name='ceiling_02' type='point'>
      <pose>-2 -2 6 0 0 0</pose>
      <cast_shadows>false</cast_shadows>
      <intensity>2</intensity>
      <direction>0 0 -1</direction>
      <diffuse>1 1 1 1</diffuse>
      <specular>0.100000001 0.100000001 0.100000001 1</specular>
      <attenuation>
        <range>9</range>
        <linear>0.01</linear>
        <constant>1</constant>
        <quadratic>0.001</quadratic>
      </attenuation>
      <spot>
        <inner_angle>0</inner_angle>
        <outer_angle>0</outer_angle>
        <falloff>0</falloff>
      </spot>
    </light>
  </world>
</sdf>
